<?xml version="1.0"?>

<robot name="arm_bot" xmlns:xacro="http://www.ros.org/wiki/xacro">
    <xacro:include filename="common_properties.xacro" />
    
    <xacro:property name="arm_base_length" value="0.1" />
    <xacro:property name="arm_base_width" value="0.1" />
    <xacro:property name="arm_base_height" value="0.02" />

    <xacro:property name="forearm_radius" value="0.02" />
    <xacro:property name="forearm_length" value="0.3" />
    <xacro:property name="hand_radius" value="0.02" />
    <xacro:property name="hand_length" value="0.3" />


    <link name="arm_base_link">
        <visual>
            <geometry>
                <box size="${arm_base_length} ${arm_base_width} ${arm_base_height}" />
            </geometry>
            <origin xyz="0 0 ${arm_base_height/2.0}" rpy="0 0 0" />
            <material name="orange" />
        </visual>

        <collision>
            <geometry>
                <box size="${arm_base_length} ${arm_base_width} ${arm_base_height}" />
            </geometry>
            <origin xyz="0 0 ${arm_base_height/2.0}" rpy="0 0 0" />   
        </collision>
        <xacro:box_inertia m="0.5" l="${arm_base_length}" w="${arm_base_width}" h="${arm_base_height}" xyz="0 0 ${arm_base_height/2.0}" rpy="0 0 0" />
    </link>

    <link name="forearm_link">
        <visual>
            <geometry>
                <cylinder radius="${forearm_radius}" length="${forearm_length}" />
            </geometry>
            <origin xyz="0 0 ${forearm_length/2.0}" rpy="0 0 0" />
            <material name="yellow" />
        </visual>

        <collision>
            <geometry>
                <cylinder radius="${forearm_radius}" length="${forearm_length}" />
            </geometry>
            <origin xyz="0 0 ${forearm_length/2.0}" rpy="0 0 0" />
        </collision>
        <xacro:cylinder_inertia m="0.3" r="${forearm_radius}" h="${forearm_length}" xyz="0 0 ${forearm_length/2.0}" rpy="0 0 0" />
    </link>

    <link name="hand_link">
        <visual>
            <geometry>
                <cylinder radius="${hand_radius}" length="${hand_length}" />
            </geometry>
            <origin xyz="0 0 ${hand_length/2.0}" rpy="0 0 0" />
            <material name="orange" />
        </visual>

        <collision>
            <geometry>
                <cylinder radius="${hand_radius}" length="${hand_length}" />
            </geometry>
            <origin xyz="0 0 ${hand_length/2.0}" rpy="0 0 0" /> 
        </collision>
        <xacro:cylinder_inertia m="0.3" r="${hand_radius}" h="${hand_length}" xyz="0 0 ${hand_length/2.0}" rpy="0 0 0" />
    </link>

    <!--Joints-->

    <joint name="arm_base_forearm_joint" type="revolute">
        <parent link="arm_base_link" />
        <child link="forearm_link" />
        <origin xyz="0 0 ${arm_base_height}" rpy="0 0 0" />
        <limit lower="0" upper="${pi/2}" effort="100" velocity="100" />
        <dynamics damping="0.1" friction="0.05" />
        <axis xyz="0 1 0" />
    </joint>

    <joint name="forearm_hand_joint" type="revolute">
        <parent link="forearm_link" />
        <child link="hand_link" />
        <origin xyz="0 0 ${forearm_length}" rpy="0 0 0" />
        <limit lower="0" upper="${pi/2}" effort="100" velocity="100" />
        <dynamics damping="0.1" friction="0.05" />
        <axis xyz="0 1 0" />
    </joint>
    
</robot>